{
 "cells": [
  {
   "cell_type": "code",
   "execution_count": 1,
   "metadata": {},
   "outputs": [],
   "source": [
    "from multiprocessing import Pool\n",
    "import os\n",
    "import papermill as pm\n",
    "from pathlib import Path\n",
    "import warnings\n",
    "warnings.simplefilter(action='ignore', category=FutureWarning)"
   ]
  },
  {
   "cell_type": "code",
   "execution_count": 2,
   "metadata": {},
   "outputs": [],
   "source": [
    "rois = []\n",
    "for file in Path('../data').iterdir():\n",
    "    if 'covid_timeseries' in str(file):\n",
    "        roi = '_'.join(file.name.split('.')[0].split('_')[2:])\n",
    "        rois.append(roi)"
   ]
  },
  {
   "cell_type": "code",
   "execution_count": 3,
   "metadata": {},
   "outputs": [],
   "source": [
    "def execute(roi):\n",
    "    os.makedirs('fits', exist_ok=True)\n",
    "    try:\n",
    "        pm.execute_notebook(\n",
    "           'MBS_epidemic_ccclinearrd_gerkin_beta.ipynb',\n",
    "           'fits/MBS_epidemic_ccclinearrd_gerkin_beta_%s.ipynb' % roi,\n",
    "           parameters=dict(roi=roi),\n",
    "           nest_asyncio=True)\n",
    "    except pm.PapermillExecutionError as e:\n",
    "        return str(e)\n",
    "    return ''"
   ]
  },
  {
   "cell_type": "code",
   "execution_count": 4,
   "metadata": {},
   "outputs": [],
   "source": [
    "pool = Pool(processes=20)\n",
    "jobs = {roi: pool.apply_async(execute, [roi]) for roi in rois[:5]}"
   ]
  },
  {
   "cell_type": "code",
   "execution_count": null,
   "metadata": {},
   "outputs": [
    {
     "data": {
      "text/plain": [
       "'US_OK, Not finished'"
      ]
     },
     "metadata": {},
     "output_type": "display_data"
    },
    {
     "data": {
      "text/plain": [
       "'Germany, Not finished'"
      ]
     },
     "metadata": {},
     "output_type": "display_data"
    },
    {
     "data": {
      "text/plain": [
       "'US_GU, Not finished'"
      ]
     },
     "metadata": {},
     "output_type": "display_data"
    },
    {
     "data": {
      "text/plain": [
       "'US_VI, Not finished'"
      ]
     },
     "metadata": {},
     "output_type": "display_data"
    },
    {
     "data": {
      "text/plain": [
       "'US_VT, Not finished'"
      ]
     },
     "metadata": {},
     "output_type": "display_data"
    }
   ],
   "source": [
    "from IPython.display import display, clear_output\n",
    "from multiprocessing import TimeoutError\n",
    "import time\n",
    "\n",
    "while True:\n",
    "    clear_output()\n",
    "    n_timeouts = 0\n",
    "    text = \"\"\n",
    "    for roi in rois[:5]:\n",
    "        try:\n",
    "            result = jobs[roi].get(timeout=1)\n",
    "        except TimeoutError:\n",
    "            result = \"Not finished\"\n",
    "            n_timeouts += 1\n",
    "        text = \"%s, %s\" % (roi, result)\n",
    "        display(text)\n",
    "    if n_timeouts == 0:\n",
    "        break\n",
    "    time.sleep(5)"
   ]
  },
  {
   "cell_type": "code",
   "execution_count": 22,
   "metadata": {},
   "outputs": [
    {
     "name": "stdout",
     "output_type": "stream",
     "text": [
      "US_OK\n",
      "\n",
      "---------------------------------------------------------------------------\n",
      "Exception encountered at \"In [12]\":\n",
      "---------------------------------------------------------------------------\n",
      "AttributeError                            Traceback (most recent call last)\n",
      "<ipython-input-12-b374f4dce4eb> in <module>\n",
      "     10     try:\n",
      "     11         fit = stanrunmodel.sampling(data=stan_data, init=init_fun, control=control, chains = n_chains,\n",
      "---> 12                                     chain_id=np.arange(n_chains), warmup=n_warmups, iter=n_iter, thin=n_thin, seed=13219)\n",
      "     13     except RuntimeError:\n",
      "     14         curr_try += 1\n",
      "\n",
      "/opt/conda/lib/python3.7/site-packages/pystan/model.py in sampling(self, data, pars, chains, iter, warmup, thin, seed, init, sample_file, diagnostic_file, verbose, algorithm, control, n_jobs, **kwargs)\n",
      "    670 \n",
      "    671         seed = pystan.misc._check_seed(seed)\n",
      "--> 672         fit = self.fit_class(data, seed)\n",
      "    673 \n",
      "    674         m_pars = fit._get_param_names()\n",
      "\n",
      "AttributeError: 'StanModel' object has no attribute 'fit_class'\n",
      "\n",
      "===========================\n",
      "Germany\n",
      "\n",
      "---------------------------------------------------------------------------\n",
      "Exception encountered at \"In [12]\":\n",
      "---------------------------------------------------------------------------\n",
      "AttributeError                            Traceback (most recent call last)\n",
      "<ipython-input-12-b374f4dce4eb> in <module>\n",
      "     10     try:\n",
      "     11         fit = stanrunmodel.sampling(data=stan_data, init=init_fun, control=control, chains = n_chains,\n",
      "---> 12                                     chain_id=np.arange(n_chains), warmup=n_warmups, iter=n_iter, thin=n_thin, seed=13219)\n",
      "     13     except RuntimeError:\n",
      "     14         curr_try += 1\n",
      "\n",
      "/opt/conda/lib/python3.7/site-packages/pystan/model.py in sampling(self, data, pars, chains, iter, warmup, thin, seed, init, sample_file, diagnostic_file, verbose, algorithm, control, n_jobs, **kwargs)\n",
      "    670 \n",
      "    671         seed = pystan.misc._check_seed(seed)\n",
      "--> 672         fit = self.fit_class(data, seed)\n",
      "    673 \n",
      "    674         m_pars = fit._get_param_names()\n",
      "\n",
      "AttributeError: 'StanModel' object has no attribute 'fit_class'\n",
      "\n",
      "===========================\n",
      "US_GU\n",
      "\n",
      "---------------------------------------------------------------------------\n",
      "Exception encountered at \"In [12]\":\n",
      "---------------------------------------------------------------------------\n",
      "AttributeError                            Traceback (most recent call last)\n",
      "<ipython-input-12-b374f4dce4eb> in <module>\n",
      "     10     try:\n",
      "     11         fit = stanrunmodel.sampling(data=stan_data, init=init_fun, control=control, chains = n_chains,\n",
      "---> 12                                     chain_id=np.arange(n_chains), warmup=n_warmups, iter=n_iter, thin=n_thin, seed=13219)\n",
      "     13     except RuntimeError:\n",
      "     14         curr_try += 1\n",
      "\n",
      "/opt/conda/lib/python3.7/site-packages/pystan/model.py in sampling(self, data, pars, chains, iter, warmup, thin, seed, init, sample_file, diagnostic_file, verbose, algorithm, control, n_jobs, **kwargs)\n",
      "    670 \n",
      "    671         seed = pystan.misc._check_seed(seed)\n",
      "--> 672         fit = self.fit_class(data, seed)\n",
      "    673 \n",
      "    674         m_pars = fit._get_param_names()\n",
      "\n",
      "AttributeError: 'StanModel' object has no attribute 'fit_class'\n",
      "\n",
      "===========================\n",
      "US_VI\n",
      "\n",
      "---------------------------------------------------------------------------\n",
      "Exception encountered at \"In [12]\":\n",
      "---------------------------------------------------------------------------\n",
      "AttributeError                            Traceback (most recent call last)\n",
      "<ipython-input-12-b374f4dce4eb> in <module>\n",
      "     10     try:\n",
      "     11         fit = stanrunmodel.sampling(data=stan_data, init=init_fun, control=control, chains = n_chains,\n",
      "---> 12                                     chain_id=np.arange(n_chains), warmup=n_warmups, iter=n_iter, thin=n_thin, seed=13219)\n",
      "     13     except RuntimeError:\n",
      "     14         curr_try += 1\n",
      "\n",
      "/opt/conda/lib/python3.7/site-packages/pystan/model.py in sampling(self, data, pars, chains, iter, warmup, thin, seed, init, sample_file, diagnostic_file, verbose, algorithm, control, n_jobs, **kwargs)\n",
      "    670 \n",
      "    671         seed = pystan.misc._check_seed(seed)\n",
      "--> 672         fit = self.fit_class(data, seed)\n",
      "    673 \n",
      "    674         m_pars = fit._get_param_names()\n",
      "\n",
      "AttributeError: 'StanModel' object has no attribute 'fit_class'\n",
      "\n",
      "===========================\n",
      "US_VT\n",
      "\n",
      "---------------------------------------------------------------------------\n",
      "Exception encountered at \"In [12]\":\n",
      "---------------------------------------------------------------------------\n",
      "AttributeError                            Traceback (most recent call last)\n",
      "<ipython-input-12-b374f4dce4eb> in <module>\n",
      "     10     try:\n",
      "     11         fit = stanrunmodel.sampling(data=stan_data, init=init_fun, control=control, chains = n_chains,\n",
      "---> 12                                     chain_id=np.arange(n_chains), warmup=n_warmups, iter=n_iter, thin=n_thin, seed=13219)\n",
      "     13     except RuntimeError:\n",
      "     14         curr_try += 1\n",
      "\n",
      "/opt/conda/lib/python3.7/site-packages/pystan/model.py in sampling(self, data, pars, chains, iter, warmup, thin, seed, init, sample_file, diagnostic_file, verbose, algorithm, control, n_jobs, **kwargs)\n",
      "    670 \n",
      "    671         seed = pystan.misc._check_seed(seed)\n",
      "--> 672         fit = self.fit_class(data, seed)\n",
      "    673 \n",
      "    674         m_pars = fit._get_param_names()\n",
      "\n",
      "AttributeError: 'StanModel' object has no attribute 'fit_class'\n",
      "\n",
      "===========================\n",
      "US_WY\n",
      "\n",
      "---------------------------------------------------------------------------\n",
      "Exception encountered at \"In [12]\":\n",
      "---------------------------------------------------------------------------\n",
      "AttributeError                            Traceback (most recent call last)\n",
      "<ipython-input-12-b374f4dce4eb> in <module>\n",
      "     10     try:\n",
      "     11         fit = stanrunmodel.sampling(data=stan_data, init=init_fun, control=control, chains = n_chains,\n",
      "---> 12                                     chain_id=np.arange(n_chains), warmup=n_warmups, iter=n_iter, thin=n_thin, seed=13219)\n",
      "     13     except RuntimeError:\n",
      "     14         curr_try += 1\n",
      "\n",
      "/opt/conda/lib/python3.7/site-packages/pystan/model.py in sampling(self, data, pars, chains, iter, warmup, thin, seed, init, sample_file, diagnostic_file, verbose, algorithm, control, n_jobs, **kwargs)\n",
      "    670 \n",
      "    671         seed = pystan.misc._check_seed(seed)\n",
      "--> 672         fit = self.fit_class(data, seed)\n",
      "    673 \n",
      "    674         m_pars = fit._get_param_names()\n",
      "\n",
      "AttributeError: 'StanModel' object has no attribute 'fit_class'\n",
      "\n",
      "===========================\n",
      "US_ND\n",
      "\n",
      "---------------------------------------------------------------------------\n",
      "Exception encountered at \"In [12]\":\n",
      "---------------------------------------------------------------------------\n",
      "AttributeError                            Traceback (most recent call last)\n",
      "<ipython-input-12-b374f4dce4eb> in <module>\n",
      "     10     try:\n",
      "     11         fit = stanrunmodel.sampling(data=stan_data, init=init_fun, control=control, chains = n_chains,\n",
      "---> 12                                     chain_id=np.arange(n_chains), warmup=n_warmups, iter=n_iter, thin=n_thin, seed=13219)\n",
      "     13     except RuntimeError:\n",
      "     14         curr_try += 1\n",
      "\n",
      "/opt/conda/lib/python3.7/site-packages/pystan/model.py in sampling(self, data, pars, chains, iter, warmup, thin, seed, init, sample_file, diagnostic_file, verbose, algorithm, control, n_jobs, **kwargs)\n",
      "    670 \n",
      "    671         seed = pystan.misc._check_seed(seed)\n",
      "--> 672         fit = self.fit_class(data, seed)\n",
      "    673 \n",
      "    674         m_pars = fit._get_param_names()\n",
      "\n",
      "AttributeError: 'StanModel' object has no attribute 'fit_class'\n",
      "\n",
      "===========================\n",
      "US_SD\n",
      "\n",
      "---------------------------------------------------------------------------\n",
      "Exception encountered at \"In [12]\":\n",
      "---------------------------------------------------------------------------\n",
      "AttributeError                            Traceback (most recent call last)\n",
      "<ipython-input-12-b374f4dce4eb> in <module>\n",
      "     10     try:\n",
      "     11         fit = stanrunmodel.sampling(data=stan_data, init=init_fun, control=control, chains = n_chains,\n",
      "---> 12                                     chain_id=np.arange(n_chains), warmup=n_warmups, iter=n_iter, thin=n_thin, seed=13219)\n",
      "     13     except RuntimeError:\n",
      "     14         curr_try += 1\n",
      "\n",
      "/opt/conda/lib/python3.7/site-packages/pystan/model.py in sampling(self, data, pars, chains, iter, warmup, thin, seed, init, sample_file, diagnostic_file, verbose, algorithm, control, n_jobs, **kwargs)\n",
      "    670 \n",
      "    671         seed = pystan.misc._check_seed(seed)\n",
      "--> 672         fit = self.fit_class(data, seed)\n",
      "    673 \n",
      "    674         m_pars = fit._get_param_names()\n",
      "\n",
      "AttributeError: 'StanModel' object has no attribute 'fit_class'\n",
      "\n",
      "===========================\n",
      "US_WV\n",
      "\n",
      "---------------------------------------------------------------------------\n",
      "Exception encountered at \"In [12]\":\n",
      "---------------------------------------------------------------------------\n",
      "AttributeError                            Traceback (most recent call last)\n",
      "<ipython-input-12-b374f4dce4eb> in <module>\n",
      "     10     try:\n",
      "     11         fit = stanrunmodel.sampling(data=stan_data, init=init_fun, control=control, chains = n_chains,\n",
      "---> 12                                     chain_id=np.arange(n_chains), warmup=n_warmups, iter=n_iter, thin=n_thin, seed=13219)\n",
      "     13     except RuntimeError:\n",
      "     14         curr_try += 1\n",
      "\n",
      "/opt/conda/lib/python3.7/site-packages/pystan/model.py in sampling(self, data, pars, chains, iter, warmup, thin, seed, init, sample_file, diagnostic_file, verbose, algorithm, control, n_jobs, **kwargs)\n",
      "    670 \n",
      "    671         seed = pystan.misc._check_seed(seed)\n",
      "--> 672         fit = self.fit_class(data, seed)\n",
      "    673 \n",
      "    674         m_pars = fit._get_param_names()\n",
      "\n",
      "AttributeError: 'StanModel' object has no attribute 'fit_class'\n",
      "\n",
      "===========================\n",
      "US_MT\n",
      "\n",
      "---------------------------------------------------------------------------\n",
      "Exception encountered at \"In [12]\":\n",
      "---------------------------------------------------------------------------\n",
      "AttributeError                            Traceback (most recent call last)\n",
      "<ipython-input-12-b374f4dce4eb> in <module>\n",
      "     10     try:\n",
      "     11         fit = stanrunmodel.sampling(data=stan_data, init=init_fun, control=control, chains = n_chains,\n",
      "---> 12                                     chain_id=np.arange(n_chains), warmup=n_warmups, iter=n_iter, thin=n_thin, seed=13219)\n",
      "     13     except RuntimeError:\n",
      "     14         curr_try += 1\n",
      "\n",
      "/opt/conda/lib/python3.7/site-packages/pystan/model.py in sampling(self, data, pars, chains, iter, warmup, thin, seed, init, sample_file, diagnostic_file, verbose, algorithm, control, n_jobs, **kwargs)\n",
      "    670 \n",
      "    671         seed = pystan.misc._check_seed(seed)\n",
      "--> 672         fit = self.fit_class(data, seed)\n",
      "    673 \n",
      "    674         m_pars = fit._get_param_names()\n",
      "\n",
      "AttributeError: 'StanModel' object has no attribute 'fit_class'\n",
      "\n",
      "===========================\n",
      "US_AK\n",
      "\n",
      "---------------------------------------------------------------------------\n",
      "Exception encountered at \"In [12]\":\n",
      "---------------------------------------------------------------------------\n",
      "AttributeError                            Traceback (most recent call last)\n",
      "<ipython-input-12-b374f4dce4eb> in <module>\n",
      "     10     try:\n",
      "     11         fit = stanrunmodel.sampling(data=stan_data, init=init_fun, control=control, chains = n_chains,\n",
      "---> 12                                     chain_id=np.arange(n_chains), warmup=n_warmups, iter=n_iter, thin=n_thin, seed=13219)\n",
      "     13     except RuntimeError:\n",
      "     14         curr_try += 1\n",
      "\n",
      "/opt/conda/lib/python3.7/site-packages/pystan/model.py in sampling(self, data, pars, chains, iter, warmup, thin, seed, init, sample_file, diagnostic_file, verbose, algorithm, control, n_jobs, **kwargs)\n",
      "    670 \n",
      "    671         seed = pystan.misc._check_seed(seed)\n",
      "--> 672         fit = self.fit_class(data, seed)\n",
      "    673 \n",
      "    674         m_pars = fit._get_param_names()\n",
      "\n",
      "AttributeError: 'StanModel' object has no attribute 'fit_class'\n",
      "\n",
      "===========================\n",
      "US_KY\n",
      "\n",
      "---------------------------------------------------------------------------\n",
      "Exception encountered at \"In [12]\":\n",
      "---------------------------------------------------------------------------\n",
      "AttributeError                            Traceback (most recent call last)\n",
      "<ipython-input-12-b374f4dce4eb> in <module>\n",
      "     10     try:\n",
      "     11         fit = stanrunmodel.sampling(data=stan_data, init=init_fun, control=control, chains = n_chains,\n",
      "---> 12                                     chain_id=np.arange(n_chains), warmup=n_warmups, iter=n_iter, thin=n_thin, seed=13219)\n",
      "     13     except RuntimeError:\n",
      "     14         curr_try += 1\n",
      "\n",
      "/opt/conda/lib/python3.7/site-packages/pystan/model.py in sampling(self, data, pars, chains, iter, warmup, thin, seed, init, sample_file, diagnostic_file, verbose, algorithm, control, n_jobs, **kwargs)\n",
      "    670 \n",
      "    671         seed = pystan.misc._check_seed(seed)\n",
      "--> 672         fit = self.fit_class(data, seed)\n",
      "    673 \n",
      "    674         m_pars = fit._get_param_names()\n",
      "\n",
      "AttributeError: 'StanModel' object has no attribute 'fit_class'\n",
      "\n",
      "===========================\n",
      "Belgium\n",
      "\n",
      "---------------------------------------------------------------------------\n",
      "Exception encountered at \"In [12]\":\n",
      "---------------------------------------------------------------------------\n",
      "AttributeError                            Traceback (most recent call last)\n",
      "<ipython-input-12-b374f4dce4eb> in <module>\n",
      "     10     try:\n",
      "     11         fit = stanrunmodel.sampling(data=stan_data, init=init_fun, control=control, chains = n_chains,\n",
      "---> 12                                     chain_id=np.arange(n_chains), warmup=n_warmups, iter=n_iter, thin=n_thin, seed=13219)\n",
      "     13     except RuntimeError:\n",
      "     14         curr_try += 1\n",
      "\n",
      "/opt/conda/lib/python3.7/site-packages/pystan/model.py in sampling(self, data, pars, chains, iter, warmup, thin, seed, init, sample_file, diagnostic_file, verbose, algorithm, control, n_jobs, **kwargs)\n",
      "    670 \n",
      "    671         seed = pystan.misc._check_seed(seed)\n",
      "--> 672         fit = self.fit_class(data, seed)\n",
      "    673 \n",
      "    674         m_pars = fit._get_param_names()\n",
      "\n",
      "AttributeError: 'StanModel' object has no attribute 'fit_class'\n",
      "\n",
      "===========================\n",
      "France\n",
      "\n",
      "---------------------------------------------------------------------------\n",
      "Exception encountered at \"In [12]\":\n",
      "---------------------------------------------------------------------------\n",
      "AttributeError                            Traceback (most recent call last)\n",
      "<ipython-input-12-b374f4dce4eb> in <module>\n",
      "     10     try:\n",
      "     11         fit = stanrunmodel.sampling(data=stan_data, init=init_fun, control=control, chains = n_chains,\n",
      "---> 12                                     chain_id=np.arange(n_chains), warmup=n_warmups, iter=n_iter, thin=n_thin, seed=13219)\n",
      "     13     except RuntimeError:\n",
      "     14         curr_try += 1\n",
      "\n",
      "/opt/conda/lib/python3.7/site-packages/pystan/model.py in sampling(self, data, pars, chains, iter, warmup, thin, seed, init, sample_file, diagnostic_file, verbose, algorithm, control, n_jobs, **kwargs)\n",
      "    670 \n",
      "    671         seed = pystan.misc._check_seed(seed)\n",
      "--> 672         fit = self.fit_class(data, seed)\n",
      "    673 \n",
      "    674         m_pars = fit._get_param_names()\n",
      "\n",
      "AttributeError: 'StanModel' object has no attribute 'fit_class'\n",
      "\n",
      "===========================\n",
      "US_ME\n",
      "\n",
      "---------------------------------------------------------------------------\n",
      "Exception encountered at \"In [12]\":\n",
      "---------------------------------------------------------------------------\n",
      "AttributeError                            Traceback (most recent call last)\n",
      "<ipython-input-12-b374f4dce4eb> in <module>\n",
      "     10     try:\n",
      "     11         fit = stanrunmodel.sampling(data=stan_data, init=init_fun, control=control, chains = n_chains,\n",
      "---> 12                                     chain_id=np.arange(n_chains), warmup=n_warmups, iter=n_iter, thin=n_thin, seed=13219)\n",
      "     13     except RuntimeError:\n",
      "     14         curr_try += 1\n",
      "\n",
      "/opt/conda/lib/python3.7/site-packages/pystan/model.py in sampling(self, data, pars, chains, iter, warmup, thin, seed, init, sample_file, diagnostic_file, verbose, algorithm, control, n_jobs, **kwargs)\n",
      "    670 \n",
      "    671         seed = pystan.misc._check_seed(seed)\n",
      "--> 672         fit = self.fit_class(data, seed)\n",
      "    673 \n",
      "    674         m_pars = fit._get_param_names()\n",
      "\n",
      "AttributeError: 'StanModel' object has no attribute 'fit_class'\n",
      "\n",
      "===========================\n",
      "US_MN\n",
      "\n",
      "---------------------------------------------------------------------------\n",
      "Exception encountered at \"In [12]\":\n",
      "---------------------------------------------------------------------------\n",
      "AttributeError                            Traceback (most recent call last)\n",
      "<ipython-input-12-b374f4dce4eb> in <module>\n",
      "     10     try:\n",
      "     11         fit = stanrunmodel.sampling(data=stan_data, init=init_fun, control=control, chains = n_chains,\n",
      "---> 12                                     chain_id=np.arange(n_chains), warmup=n_warmups, iter=n_iter, thin=n_thin, seed=13219)\n",
      "     13     except RuntimeError:\n",
      "     14         curr_try += 1\n",
      "\n",
      "/opt/conda/lib/python3.7/site-packages/pystan/model.py in sampling(self, data, pars, chains, iter, warmup, thin, seed, init, sample_file, diagnostic_file, verbose, algorithm, control, n_jobs, **kwargs)\n",
      "    670 \n",
      "    671         seed = pystan.misc._check_seed(seed)\n",
      "--> 672         fit = self.fit_class(data, seed)\n",
      "    673 \n",
      "    674         m_pars = fit._get_param_names()\n",
      "\n",
      "AttributeError: 'StanModel' object has no attribute 'fit_class'\n",
      "\n",
      "===========================\n",
      "Switzerland\n",
      "\n",
      "---------------------------------------------------------------------------\n",
      "Exception encountered at \"In [12]\":\n",
      "---------------------------------------------------------------------------\n",
      "AttributeError                            Traceback (most recent call last)\n",
      "<ipython-input-12-b374f4dce4eb> in <module>\n",
      "     10     try:\n",
      "     11         fit = stanrunmodel.sampling(data=stan_data, init=init_fun, control=control, chains = n_chains,\n",
      "---> 12                                     chain_id=np.arange(n_chains), warmup=n_warmups, iter=n_iter, thin=n_thin, seed=13219)\n",
      "     13     except RuntimeError:\n",
      "     14         curr_try += 1\n",
      "\n",
      "/opt/conda/lib/python3.7/site-packages/pystan/model.py in sampling(self, data, pars, chains, iter, warmup, thin, seed, init, sample_file, diagnostic_file, verbose, algorithm, control, n_jobs, **kwargs)\n",
      "    670 \n",
      "    671         seed = pystan.misc._check_seed(seed)\n",
      "--> 672         fit = self.fit_class(data, seed)\n",
      "    673 \n",
      "    674         m_pars = fit._get_param_names()\n",
      "\n",
      "AttributeError: 'StanModel' object has no attribute 'fit_class'\n",
      "\n",
      "===========================\n",
      "US_NY\n",
      "\n",
      "---------------------------------------------------------------------------\n",
      "Exception encountered at \"In [12]\":\n",
      "---------------------------------------------------------------------------\n",
      "AttributeError                            Traceback (most recent call last)\n",
      "<ipython-input-12-b374f4dce4eb> in <module>\n",
      "     10     try:\n",
      "     11         fit = stanrunmodel.sampling(data=stan_data, init=init_fun, control=control, chains = n_chains,\n",
      "---> 12                                     chain_id=np.arange(n_chains), warmup=n_warmups, iter=n_iter, thin=n_thin, seed=13219)\n",
      "     13     except RuntimeError:\n",
      "     14         curr_try += 1\n",
      "\n",
      "/opt/conda/lib/python3.7/site-packages/pystan/model.py in sampling(self, data, pars, chains, iter, warmup, thin, seed, init, sample_file, diagnostic_file, verbose, algorithm, control, n_jobs, **kwargs)\n",
      "    670 \n",
      "    671         seed = pystan.misc._check_seed(seed)\n",
      "--> 672         fit = self.fit_class(data, seed)\n",
      "    673 \n",
      "    674         m_pars = fit._get_param_names()\n",
      "\n",
      "AttributeError: 'StanModel' object has no attribute 'fit_class'\n",
      "\n",
      "===========================\n",
      "US_DE\n",
      "\n",
      "---------------------------------------------------------------------------\n",
      "Exception encountered at \"In [12]\":\n",
      "---------------------------------------------------------------------------\n",
      "AttributeError                            Traceback (most recent call last)\n",
      "<ipython-input-12-b374f4dce4eb> in <module>\n",
      "     10     try:\n",
      "     11         fit = stanrunmodel.sampling(data=stan_data, init=init_fun, control=control, chains = n_chains,\n",
      "---> 12                                     chain_id=np.arange(n_chains), warmup=n_warmups, iter=n_iter, thin=n_thin, seed=13219)\n",
      "     13     except RuntimeError:\n",
      "     14         curr_try += 1\n",
      "\n",
      "/opt/conda/lib/python3.7/site-packages/pystan/model.py in sampling(self, data, pars, chains, iter, warmup, thin, seed, init, sample_file, diagnostic_file, verbose, algorithm, control, n_jobs, **kwargs)\n",
      "    670 \n",
      "    671         seed = pystan.misc._check_seed(seed)\n",
      "--> 672         fit = self.fit_class(data, seed)\n",
      "    673 \n",
      "    674         m_pars = fit._get_param_names()\n",
      "\n",
      "AttributeError: 'StanModel' object has no attribute 'fit_class'\n",
      "\n",
      "===========================\n",
      "US_TN\n",
      "\n",
      "---------------------------------------------------------------------------\n",
      "Exception encountered at \"In [12]\":\n",
      "---------------------------------------------------------------------------\n",
      "AttributeError                            Traceback (most recent call last)\n",
      "<ipython-input-12-b374f4dce4eb> in <module>\n",
      "     10     try:\n",
      "     11         fit = stanrunmodel.sampling(data=stan_data, init=init_fun, control=control, chains = n_chains,\n",
      "---> 12                                     chain_id=np.arange(n_chains), warmup=n_warmups, iter=n_iter, thin=n_thin, seed=13219)\n",
      "     13     except RuntimeError:\n",
      "     14         curr_try += 1\n",
      "\n",
      "/opt/conda/lib/python3.7/site-packages/pystan/model.py in sampling(self, data, pars, chains, iter, warmup, thin, seed, init, sample_file, diagnostic_file, verbose, algorithm, control, n_jobs, **kwargs)\n",
      "    670 \n",
      "    671         seed = pystan.misc._check_seed(seed)\n",
      "--> 672         fit = self.fit_class(data, seed)\n",
      "    673 \n",
      "    674         m_pars = fit._get_param_names()\n",
      "\n",
      "AttributeError: 'StanModel' object has no attribute 'fit_class'\n",
      "\n",
      "===========================\n",
      "US_TX\n",
      "\n",
      "---------------------------------------------------------------------------\n",
      "Exception encountered at \"In [12]\":\n",
      "---------------------------------------------------------------------------\n",
      "AttributeError                            Traceback (most recent call last)\n",
      "<ipython-input-12-b374f4dce4eb> in <module>\n",
      "     10     try:\n",
      "     11         fit = stanrunmodel.sampling(data=stan_data, init=init_fun, control=control, chains = n_chains,\n",
      "---> 12                                     chain_id=np.arange(n_chains), warmup=n_warmups, iter=n_iter, thin=n_thin, seed=13219)\n",
      "     13     except RuntimeError:\n",
      "     14         curr_try += 1\n",
      "\n",
      "/opt/conda/lib/python3.7/site-packages/pystan/model.py in sampling(self, data, pars, chains, iter, warmup, thin, seed, init, sample_file, diagnostic_file, verbose, algorithm, control, n_jobs, **kwargs)\n",
      "    670 \n",
      "    671         seed = pystan.misc._check_seed(seed)\n",
      "--> 672         fit = self.fit_class(data, seed)\n",
      "    673 \n",
      "    674         m_pars = fit._get_param_names()\n",
      "\n",
      "AttributeError: 'StanModel' object has no attribute 'fit_class'\n",
      "\n",
      "===========================\n",
      "US_NM\n",
      "\n",
      "---------------------------------------------------------------------------\n",
      "Exception encountered at \"In [12]\":\n",
      "---------------------------------------------------------------------------\n",
      "AttributeError                            Traceback (most recent call last)\n",
      "<ipython-input-12-b374f4dce4eb> in <module>\n",
      "     10     try:\n",
      "     11         fit = stanrunmodel.sampling(data=stan_data, init=init_fun, control=control, chains = n_chains,\n",
      "---> 12                                     chain_id=np.arange(n_chains), warmup=n_warmups, iter=n_iter, thin=n_thin, seed=13219)\n",
      "     13     except RuntimeError:\n",
      "     14         curr_try += 1\n",
      "\n",
      "/opt/conda/lib/python3.7/site-packages/pystan/model.py in sampling(self, data, pars, chains, iter, warmup, thin, seed, init, sample_file, diagnostic_file, verbose, algorithm, control, n_jobs, **kwargs)\n",
      "    670 \n",
      "    671         seed = pystan.misc._check_seed(seed)\n",
      "--> 672         fit = self.fit_class(data, seed)\n",
      "    673 \n",
      "    674         m_pars = fit._get_param_names()\n",
      "\n",
      "AttributeError: 'StanModel' object has no attribute 'fit_class'\n",
      "\n",
      "===========================\n",
      "US_HI\n",
      "\n",
      "---------------------------------------------------------------------------\n",
      "Exception encountered at \"In [12]\":\n",
      "---------------------------------------------------------------------------\n",
      "AttributeError                            Traceback (most recent call last)\n",
      "<ipython-input-12-b374f4dce4eb> in <module>\n",
      "     10     try:\n",
      "     11         fit = stanrunmodel.sampling(data=stan_data, init=init_fun, control=control, chains = n_chains,\n",
      "---> 12                                     chain_id=np.arange(n_chains), warmup=n_warmups, iter=n_iter, thin=n_thin, seed=13219)\n",
      "     13     except RuntimeError:\n",
      "     14         curr_try += 1\n",
      "\n",
      "/opt/conda/lib/python3.7/site-packages/pystan/model.py in sampling(self, data, pars, chains, iter, warmup, thin, seed, init, sample_file, diagnostic_file, verbose, algorithm, control, n_jobs, **kwargs)\n",
      "    670 \n",
      "    671         seed = pystan.misc._check_seed(seed)\n",
      "--> 672         fit = self.fit_class(data, seed)\n",
      "    673 \n",
      "    674         m_pars = fit._get_param_names()\n",
      "\n",
      "AttributeError: 'StanModel' object has no attribute 'fit_class'\n",
      "\n",
      "===========================\n",
      "US_RI\n",
      "\n",
      "---------------------------------------------------------------------------\n",
      "Exception encountered at \"In [12]\":\n",
      "---------------------------------------------------------------------------\n",
      "AttributeError                            Traceback (most recent call last)\n",
      "<ipython-input-12-b374f4dce4eb> in <module>\n",
      "     10     try:\n",
      "     11         fit = stanrunmodel.sampling(data=stan_data, init=init_fun, control=control, chains = n_chains,\n",
      "---> 12                                     chain_id=np.arange(n_chains), warmup=n_warmups, iter=n_iter, thin=n_thin, seed=13219)\n",
      "     13     except RuntimeError:\n",
      "     14         curr_try += 1\n",
      "\n",
      "/opt/conda/lib/python3.7/site-packages/pystan/model.py in sampling(self, data, pars, chains, iter, warmup, thin, seed, init, sample_file, diagnostic_file, verbose, algorithm, control, n_jobs, **kwargs)\n",
      "    670 \n",
      "    671         seed = pystan.misc._check_seed(seed)\n",
      "--> 672         fit = self.fit_class(data, seed)\n",
      "    673 \n",
      "    674         m_pars = fit._get_param_names()\n",
      "\n",
      "AttributeError: 'StanModel' object has no attribute 'fit_class'\n",
      "\n",
      "===========================\n",
      "US_NH\n",
      "\n",
      "---------------------------------------------------------------------------\n",
      "Exception encountered at \"In [12]\":\n",
      "---------------------------------------------------------------------------\n",
      "AttributeError                            Traceback (most recent call last)\n",
      "<ipython-input-12-b374f4dce4eb> in <module>\n",
      "     10     try:\n",
      "     11         fit = stanrunmodel.sampling(data=stan_data, init=init_fun, control=control, chains = n_chains,\n",
      "---> 12                                     chain_id=np.arange(n_chains), warmup=n_warmups, iter=n_iter, thin=n_thin, seed=13219)\n",
      "     13     except RuntimeError:\n",
      "     14         curr_try += 1\n",
      "\n",
      "/opt/conda/lib/python3.7/site-packages/pystan/model.py in sampling(self, data, pars, chains, iter, warmup, thin, seed, init, sample_file, diagnostic_file, verbose, algorithm, control, n_jobs, **kwargs)\n",
      "    670 \n",
      "    671         seed = pystan.misc._check_seed(seed)\n",
      "--> 672         fit = self.fit_class(data, seed)\n",
      "    673 \n",
      "    674         m_pars = fit._get_param_names()\n",
      "\n",
      "AttributeError: 'StanModel' object has no attribute 'fit_class'\n",
      "\n",
      "===========================\n",
      "Iran\n",
      "\n",
      "---------------------------------------------------------------------------\n",
      "Exception encountered at \"In [12]\":\n",
      "---------------------------------------------------------------------------\n",
      "AttributeError                            Traceback (most recent call last)\n",
      "<ipython-input-12-b374f4dce4eb> in <module>\n",
      "     10     try:\n",
      "     11         fit = stanrunmodel.sampling(data=stan_data, init=init_fun, control=control, chains = n_chains,\n",
      "---> 12                                     chain_id=np.arange(n_chains), warmup=n_warmups, iter=n_iter, thin=n_thin, seed=13219)\n",
      "     13     except RuntimeError:\n",
      "     14         curr_try += 1\n",
      "\n",
      "/opt/conda/lib/python3.7/site-packages/pystan/model.py in sampling(self, data, pars, chains, iter, warmup, thin, seed, init, sample_file, diagnostic_file, verbose, algorithm, control, n_jobs, **kwargs)\n",
      "    670 \n",
      "    671         seed = pystan.misc._check_seed(seed)\n",
      "--> 672         fit = self.fit_class(data, seed)\n",
      "    673 \n",
      "    674         m_pars = fit._get_param_names()\n",
      "\n",
      "AttributeError: 'StanModel' object has no attribute 'fit_class'\n",
      "\n",
      "===========================\n",
      "US_DC\n",
      "\n",
      "---------------------------------------------------------------------------\n",
      "Exception encountered at \"In [12]\":\n",
      "---------------------------------------------------------------------------\n",
      "AttributeError                            Traceback (most recent call last)\n",
      "<ipython-input-12-b374f4dce4eb> in <module>\n",
      "     10     try:\n",
      "     11         fit = stanrunmodel.sampling(data=stan_data, init=init_fun, control=control, chains = n_chains,\n",
      "---> 12                                     chain_id=np.arange(n_chains), warmup=n_warmups, iter=n_iter, thin=n_thin, seed=13219)\n",
      "     13     except RuntimeError:\n",
      "     14         curr_try += 1\n",
      "\n",
      "/opt/conda/lib/python3.7/site-packages/pystan/model.py in sampling(self, data, pars, chains, iter, warmup, thin, seed, init, sample_file, diagnostic_file, verbose, algorithm, control, n_jobs, **kwargs)\n",
      "    670 \n",
      "    671         seed = pystan.misc._check_seed(seed)\n",
      "--> 672         fit = self.fit_class(data, seed)\n",
      "    673 \n",
      "    674         m_pars = fit._get_param_names()\n",
      "\n",
      "AttributeError: 'StanModel' object has no attribute 'fit_class'\n",
      "\n",
      "===========================\n",
      "Italy\n",
      "\n",
      "---------------------------------------------------------------------------\n",
      "Exception encountered at \"In [12]\":\n",
      "---------------------------------------------------------------------------\n",
      "AttributeError                            Traceback (most recent call last)\n",
      "<ipython-input-12-b374f4dce4eb> in <module>\n",
      "     10     try:\n",
      "     11         fit = stanrunmodel.sampling(data=stan_data, init=init_fun, control=control, chains = n_chains,\n",
      "---> 12                                     chain_id=np.arange(n_chains), warmup=n_warmups, iter=n_iter, thin=n_thin, seed=13219)\n",
      "     13     except RuntimeError:\n",
      "     14         curr_try += 1\n",
      "\n",
      "/opt/conda/lib/python3.7/site-packages/pystan/model.py in sampling(self, data, pars, chains, iter, warmup, thin, seed, init, sample_file, diagnostic_file, verbose, algorithm, control, n_jobs, **kwargs)\n",
      "    670 \n",
      "    671         seed = pystan.misc._check_seed(seed)\n",
      "--> 672         fit = self.fit_class(data, seed)\n",
      "    673 \n",
      "    674         m_pars = fit._get_param_names()\n",
      "\n",
      "AttributeError: 'StanModel' object has no attribute 'fit_class'\n",
      "\n",
      "===========================\n",
      "United Kingdom\n",
      "\n",
      "---------------------------------------------------------------------------\n",
      "Exception encountered at \"In [12]\":\n",
      "---------------------------------------------------------------------------\n",
      "AttributeError                            Traceback (most recent call last)\n",
      "<ipython-input-12-b374f4dce4eb> in <module>\n",
      "     10     try:\n",
      "     11         fit = stanrunmodel.sampling(data=stan_data, init=init_fun, control=control, chains = n_chains,\n",
      "---> 12                                     chain_id=np.arange(n_chains), warmup=n_warmups, iter=n_iter, thin=n_thin, seed=13219)\n",
      "     13     except RuntimeError:\n",
      "     14         curr_try += 1\n",
      "\n",
      "/opt/conda/lib/python3.7/site-packages/pystan/model.py in sampling(self, data, pars, chains, iter, warmup, thin, seed, init, sample_file, diagnostic_file, verbose, algorithm, control, n_jobs, **kwargs)\n",
      "    670 \n",
      "    671         seed = pystan.misc._check_seed(seed)\n",
      "--> 672         fit = self.fit_class(data, seed)\n",
      "    673 \n",
      "    674         m_pars = fit._get_param_names()\n",
      "\n",
      "AttributeError: 'StanModel' object has no attribute 'fit_class'\n",
      "\n",
      "===========================\n",
      "US_IA\n",
      "\n",
      "---------------------------------------------------------------------------\n",
      "Exception encountered at \"In [12]\":\n",
      "---------------------------------------------------------------------------\n",
      "AttributeError                            Traceback (most recent call last)\n",
      "<ipython-input-12-b374f4dce4eb> in <module>\n",
      "     10     try:\n",
      "     11         fit = stanrunmodel.sampling(data=stan_data, init=init_fun, control=control, chains = n_chains,\n",
      "---> 12                                     chain_id=np.arange(n_chains), warmup=n_warmups, iter=n_iter, thin=n_thin, seed=13219)\n",
      "     13     except RuntimeError:\n",
      "     14         curr_try += 1\n",
      "\n",
      "/opt/conda/lib/python3.7/site-packages/pystan/model.py in sampling(self, data, pars, chains, iter, warmup, thin, seed, init, sample_file, diagnostic_file, verbose, algorithm, control, n_jobs, **kwargs)\n",
      "    670 \n",
      "    671         seed = pystan.misc._check_seed(seed)\n",
      "--> 672         fit = self.fit_class(data, seed)\n",
      "    673 \n",
      "    674         m_pars = fit._get_param_names()\n",
      "\n",
      "AttributeError: 'StanModel' object has no attribute 'fit_class'\n",
      "\n",
      "===========================\n",
      "US_NJ\n",
      "\n",
      "---------------------------------------------------------------------------\n",
      "Exception encountered at \"In [12]\":\n",
      "---------------------------------------------------------------------------\n",
      "AttributeError                            Traceback (most recent call last)\n",
      "<ipython-input-12-b374f4dce4eb> in <module>\n",
      "     10     try:\n",
      "     11         fit = stanrunmodel.sampling(data=stan_data, init=init_fun, control=control, chains = n_chains,\n",
      "---> 12                                     chain_id=np.arange(n_chains), warmup=n_warmups, iter=n_iter, thin=n_thin, seed=13219)\n",
      "     13     except RuntimeError:\n",
      "     14         curr_try += 1\n",
      "\n",
      "/opt/conda/lib/python3.7/site-packages/pystan/model.py in sampling(self, data, pars, chains, iter, warmup, thin, seed, init, sample_file, diagnostic_file, verbose, algorithm, control, n_jobs, **kwargs)\n",
      "    670 \n",
      "    671         seed = pystan.misc._check_seed(seed)\n",
      "--> 672         fit = self.fit_class(data, seed)\n",
      "    673 \n",
      "    674         m_pars = fit._get_param_names()\n",
      "\n",
      "AttributeError: 'StanModel' object has no attribute 'fit_class'\n",
      "\n",
      "===========================\n",
      "Netherlands\n",
      "\n",
      "---------------------------------------------------------------------------\n",
      "Exception encountered at \"In [12]\":\n",
      "---------------------------------------------------------------------------\n",
      "AttributeError                            Traceback (most recent call last)\n",
      "<ipython-input-12-b374f4dce4eb> in <module>\n",
      "     10     try:\n",
      "     11         fit = stanrunmodel.sampling(data=stan_data, init=init_fun, control=control, chains = n_chains,\n",
      "---> 12                                     chain_id=np.arange(n_chains), warmup=n_warmups, iter=n_iter, thin=n_thin, seed=13219)\n",
      "     13     except RuntimeError:\n",
      "     14         curr_try += 1\n",
      "\n",
      "/opt/conda/lib/python3.7/site-packages/pystan/model.py in sampling(self, data, pars, chains, iter, warmup, thin, seed, init, sample_file, diagnostic_file, verbose, algorithm, control, n_jobs, **kwargs)\n",
      "    670 \n",
      "    671         seed = pystan.misc._check_seed(seed)\n",
      "--> 672         fit = self.fit_class(data, seed)\n",
      "    673 \n",
      "    674         m_pars = fit._get_param_names()\n",
      "\n",
      "AttributeError: 'StanModel' object has no attribute 'fit_class'\n",
      "\n",
      "===========================\n",
      "US_MD\n",
      "\n",
      "---------------------------------------------------------------------------\n",
      "Exception encountered at \"In [12]\":\n",
      "---------------------------------------------------------------------------\n",
      "AttributeError                            Traceback (most recent call last)\n",
      "<ipython-input-12-b374f4dce4eb> in <module>\n",
      "     10     try:\n",
      "     11         fit = stanrunmodel.sampling(data=stan_data, init=init_fun, control=control, chains = n_chains,\n",
      "---> 12                                     chain_id=np.arange(n_chains), warmup=n_warmups, iter=n_iter, thin=n_thin, seed=13219)\n",
      "     13     except RuntimeError:\n",
      "     14         curr_try += 1\n",
      "\n",
      "/opt/conda/lib/python3.7/site-packages/pystan/model.py in sampling(self, data, pars, chains, iter, warmup, thin, seed, init, sample_file, diagnostic_file, verbose, algorithm, control, n_jobs, **kwargs)\n",
      "    670 \n",
      "    671         seed = pystan.misc._check_seed(seed)\n",
      "--> 672         fit = self.fit_class(data, seed)\n",
      "    673 \n",
      "    674         m_pars = fit._get_param_names()\n",
      "\n",
      "AttributeError: 'StanModel' object has no attribute 'fit_class'\n",
      "\n",
      "===========================\n",
      "US_AR\n",
      "\n",
      "---------------------------------------------------------------------------\n",
      "Exception encountered at \"In [12]\":\n",
      "---------------------------------------------------------------------------\n",
      "AttributeError                            Traceback (most recent call last)\n",
      "<ipython-input-12-b374f4dce4eb> in <module>\n",
      "     10     try:\n",
      "     11         fit = stanrunmodel.sampling(data=stan_data, init=init_fun, control=control, chains = n_chains,\n",
      "---> 12                                     chain_id=np.arange(n_chains), warmup=n_warmups, iter=n_iter, thin=n_thin, seed=13219)\n",
      "     13     except RuntimeError:\n",
      "     14         curr_try += 1\n",
      "\n",
      "/opt/conda/lib/python3.7/site-packages/pystan/model.py in sampling(self, data, pars, chains, iter, warmup, thin, seed, init, sample_file, diagnostic_file, verbose, algorithm, control, n_jobs, **kwargs)\n",
      "    670 \n",
      "    671         seed = pystan.misc._check_seed(seed)\n",
      "--> 672         fit = self.fit_class(data, seed)\n",
      "    673 \n",
      "    674         m_pars = fit._get_param_names()\n",
      "\n",
      "AttributeError: 'StanModel' object has no attribute 'fit_class'\n",
      "\n",
      "===========================\n",
      "Spain\n",
      "\n",
      "---------------------------------------------------------------------------\n",
      "Exception encountered at \"In [12]\":\n",
      "---------------------------------------------------------------------------\n",
      "AttributeError                            Traceback (most recent call last)\n",
      "<ipython-input-12-b374f4dce4eb> in <module>\n",
      "     10     try:\n",
      "     11         fit = stanrunmodel.sampling(data=stan_data, init=init_fun, control=control, chains = n_chains,\n",
      "---> 12                                     chain_id=np.arange(n_chains), warmup=n_warmups, iter=n_iter, thin=n_thin, seed=13219)\n",
      "     13     except RuntimeError:\n",
      "     14         curr_try += 1\n",
      "\n",
      "/opt/conda/lib/python3.7/site-packages/pystan/model.py in sampling(self, data, pars, chains, iter, warmup, thin, seed, init, sample_file, diagnostic_file, verbose, algorithm, control, n_jobs, **kwargs)\n",
      "    670 \n",
      "    671         seed = pystan.misc._check_seed(seed)\n",
      "--> 672         fit = self.fit_class(data, seed)\n",
      "    673 \n",
      "    674         m_pars = fit._get_param_names()\n",
      "\n",
      "AttributeError: 'StanModel' object has no attribute 'fit_class'\n",
      "\n",
      "===========================\n",
      "Korea, South\n",
      "\n",
      "---------------------------------------------------------------------------\n",
      "Exception encountered at \"In [12]\":\n",
      "---------------------------------------------------------------------------\n",
      "AttributeError                            Traceback (most recent call last)\n",
      "<ipython-input-12-b374f4dce4eb> in <module>\n",
      "     10     try:\n",
      "     11         fit = stanrunmodel.sampling(data=stan_data, init=init_fun, control=control, chains = n_chains,\n",
      "---> 12                                     chain_id=np.arange(n_chains), warmup=n_warmups, iter=n_iter, thin=n_thin, seed=13219)\n",
      "     13     except RuntimeError:\n",
      "     14         curr_try += 1\n",
      "\n",
      "/opt/conda/lib/python3.7/site-packages/pystan/model.py in sampling(self, data, pars, chains, iter, warmup, thin, seed, init, sample_file, diagnostic_file, verbose, algorithm, control, n_jobs, **kwargs)\n",
      "    670 \n",
      "    671         seed = pystan.misc._check_seed(seed)\n",
      "--> 672         fit = self.fit_class(data, seed)\n",
      "    673 \n",
      "    674         m_pars = fit._get_param_names()\n",
      "\n",
      "AttributeError: 'StanModel' object has no attribute 'fit_class'\n",
      "\n",
      "===========================\n",
      "Turkey\n",
      "\n",
      "---------------------------------------------------------------------------\n",
      "Exception encountered at \"In [12]\":\n",
      "---------------------------------------------------------------------------\n",
      "AttributeError                            Traceback (most recent call last)\n",
      "<ipython-input-12-b374f4dce4eb> in <module>\n",
      "     10     try:\n",
      "     11         fit = stanrunmodel.sampling(data=stan_data, init=init_fun, control=control, chains = n_chains,\n",
      "---> 12                                     chain_id=np.arange(n_chains), warmup=n_warmups, iter=n_iter, thin=n_thin, seed=13219)\n",
      "     13     except RuntimeError:\n",
      "     14         curr_try += 1\n",
      "\n",
      "/opt/conda/lib/python3.7/site-packages/pystan/model.py in sampling(self, data, pars, chains, iter, warmup, thin, seed, init, sample_file, diagnostic_file, verbose, algorithm, control, n_jobs, **kwargs)\n",
      "    670 \n",
      "    671         seed = pystan.misc._check_seed(seed)\n",
      "--> 672         fit = self.fit_class(data, seed)\n",
      "    673 \n",
      "    674         m_pars = fit._get_param_names()\n",
      "\n",
      "AttributeError: 'StanModel' object has no attribute 'fit_class'\n",
      "\n",
      "===========================\n",
      "China\n",
      "\n",
      "---------------------------------------------------------------------------\n",
      "Exception encountered at \"In [12]\":\n",
      "---------------------------------------------------------------------------\n",
      "AttributeError                            Traceback (most recent call last)\n",
      "<ipython-input-12-b374f4dce4eb> in <module>\n",
      "     10     try:\n",
      "     11         fit = stanrunmodel.sampling(data=stan_data, init=init_fun, control=control, chains = n_chains,\n",
      "---> 12                                     chain_id=np.arange(n_chains), warmup=n_warmups, iter=n_iter, thin=n_thin, seed=13219)\n",
      "     13     except RuntimeError:\n",
      "     14         curr_try += 1\n",
      "\n",
      "/opt/conda/lib/python3.7/site-packages/pystan/model.py in sampling(self, data, pars, chains, iter, warmup, thin, seed, init, sample_file, diagnostic_file, verbose, algorithm, control, n_jobs, **kwargs)\n",
      "    670 \n",
      "    671         seed = pystan.misc._check_seed(seed)\n",
      "--> 672         fit = self.fit_class(data, seed)\n",
      "    673 \n",
      "    674         m_pars = fit._get_param_names()\n",
      "\n",
      "AttributeError: 'StanModel' object has no attribute 'fit_class'\n",
      "\n",
      "===========================\n",
      "US_MI\n",
      "\n",
      "---------------------------------------------------------------------------\n",
      "Exception encountered at \"In [12]\":\n",
      "---------------------------------------------------------------------------\n",
      "AttributeError                            Traceback (most recent call last)\n",
      "<ipython-input-12-b374f4dce4eb> in <module>\n",
      "     10     try:\n",
      "     11         fit = stanrunmodel.sampling(data=stan_data, init=init_fun, control=control, chains = n_chains,\n",
      "---> 12                                     chain_id=np.arange(n_chains), warmup=n_warmups, iter=n_iter, thin=n_thin, seed=13219)\n",
      "     13     except RuntimeError:\n",
      "     14         curr_try += 1\n",
      "\n",
      "/opt/conda/lib/python3.7/site-packages/pystan/model.py in sampling(self, data, pars, chains, iter, warmup, thin, seed, init, sample_file, diagnostic_file, verbose, algorithm, control, n_jobs, **kwargs)\n",
      "    670 \n",
      "    671         seed = pystan.misc._check_seed(seed)\n",
      "--> 672         fit = self.fit_class(data, seed)\n",
      "    673 \n",
      "    674         m_pars = fit._get_param_names()\n",
      "\n",
      "AttributeError: 'StanModel' object has no attribute 'fit_class'\n",
      "\n",
      "===========================\n"
     ]
    }
   ],
   "source": [
    "for roi in rois:\n",
    "    result = results[roi]\n",
    "    if result: # If there was an error:\n",
    "        print(roi)\n",
    "        print(result)\n",
    "        print(\"===========================\")"
   ]
  },
  {
   "cell_type": "code",
   "execution_count": 7,
   "metadata": {},
   "outputs": [],
   "source": [
    "#try:\n",
    "#    result = pm.execute_notebook(\n",
    "#       'dummy.ipynb',\n",
    "#       'dummy-2.ipynb',\n",
    "#       parameters=dict(roi='hethhh'),\n",
    "#       nest_asyncio=True)\n",
    "#except pm.PapermillExecutionError:\n",
    "#    pass"
   ]
  },
  {
   "cell_type": "code",
   "execution_count": null,
   "metadata": {},
   "outputs": [],
   "source": []
  }
 ],
 "metadata": {
  "kernelspec": {
   "display_name": "Python 3",
   "language": "python",
   "name": "python3"
  },
  "language_info": {
   "codemirror_mode": {
    "name": "ipython",
    "version": 3
   },
   "file_extension": ".py",
   "mimetype": "text/x-python",
   "name": "python",
   "nbconvert_exporter": "python",
   "pygments_lexer": "ipython3",
   "version": "3.7.4"
  }
 },
 "nbformat": 4,
 "nbformat_minor": 4
}
